<mujoco model ="Bowlinghand">
    <worldbody>
		<body name="arm" pos="19.32 0 1.1" euler="0 0 270">
			<geom type="sphere" size=".05"/>
			<joint name="armschwung" type="hinge" pos="0 0 0" axis="1 0 0" limited="true" range="-90 70" margin=".3"/>
			<body pos="0 0 -.3">
				<geom type="cylinder" size=".05 .3" />
				<body name="hand" pos="0 0 -.35">
					<geom type="box" size=".05 .01 .06"/>
					<body pos="0 0 -.1" name="handflaeche">
						<geom type="box" size=".05 .01 .06"/>
						<geom type="ellipsoid" size=".1 .03 .1" rgba="1 1 1 .5"/>
						<body name="haltezylinder" pos="0 0 0" euler = "0 0 180">
							<joint name="handgelenk" type="hinge" pos="0 0 0" axis="1 0 0"/>
							<geom type="sphere" size=".03" euler="90 0 0" margin=".3" gap=".3"/>
						</body>
					</body>
				</body>
			</body>
		</body>
		
    </worldbody>

	<actuator>
		<adhesion name="adhere_arm" body="haltezylinder" ctrlrange="0 10" gain="200"/>
		<motor name="schwung" joint="armschwung" ctrllimited="true" ctrlrange="-100 100" gear="50"/>
		<motor name="rotation" joint="handgelenk" ctrllimited="true" ctrlrange="-50 50"/>
		<!--<position name="drehung" joint="armdrehung" ctrlrange="-1 1" ctrllimited="true"/>-->
	</actuator>
	
	
</mujoco>
